Workbook

Sheet Свод
B1: Очная | D1: Очно-заочная | F1: Заочная
B2: Всего | C2: Контракт | D2: Всего | E2: Контракт | F2: Всего | G2: Контракт
A3: Бакалавриат | B3: =Бакалавриат!B35+'ВО ЭФ '!B6 -> 5114 | C3: =Бакалавриат!C35+'ВО ЭФ '!C6 -> 811 | D3: =Бакалавриат!D35+'ВО ЭФ '!D6 -> 2296 | E3: =Бакалавриат!E35+'ВО ЭФ '!E6 -> 620 | F3: =Бакалавриат!F35+'ВО ЭФ '!F6 -> 3911 | G3: =Бакалавриат!G35+'ВО ЭФ '!G6 -> 855
A4: Специалитет | B4: =Специалитет!B35 -> 351 | C4: =Специалитет!C35 -> 144 | D4: =Специалитет!D35 -> 0 | E4: =Специалитет!E35 -> 0 | F4: =Специалитет!F35 -> 237 | G4: =Специалитет!G35 -> 36
A5: Магистратура | B5: =Магистратура!B35 -> 1321 | C5: =Магистратура!C35 -> 65 | D5: =Магистратура!D35 -> 104 | E5: =Магистратура!E35 -> 46 | F5: =Магистратура!F35 -> 1489 | G5: =Магистратура!G35 -> 534
A6: СПО | B6: ='СПО БК'!C9+'СПО ПК'!C9+'СПО ВК'!C11+'СПО ЭФ'!B10 -> 1199 | C6: ='СПО БК'!D9+'СПО ПК'!D9+'СПО ВК'!D11+'СПО ЭФ'!C10 -> 360 | D6: 0 | E6: 0 | F6: 0 | G6: 0
A7: Аспирантура

Sheet СПО БК
C1: Очная
C2: Всего | D2: Контракт
A3: 35.02.05 | B3: Агрономия | C3: 33 | D3: 5
A4: 19.02.11 | B4: Технология продуктов питания из растительного сырья | C4: 101 | D4: 7
A5: 15.02.12 | B5: Монтаж, техническое обслуживание и ремонт промышленного оборудования (по отраслям) | C5: 56 | D5: 0
A6: 15.02.17 | B6: Монтаж, техническое обслуживания, эксплуатация и ремонт промышленного оборудования (по отраслям) | C6: 46 | D6: 2
A7: 38.02.06 | B7: Финансы | C7: 53 | D7: 12
A8: 43.02.16 | B8: Туризм и гостеприимство | C8: 59 | D8: 21
A9: Всего | C9: 348 | D9: 47

Sheet СПО ПК
C1: Очная
C2: Всего | D2: Контракт
A3: 35.02.05 | B3: Агрономия | C3: 39 | D3: 0
A4: 21.02.19 | B4: Землеустройство | C4: 7 | D4: 0
A5: 15.02.19 | B5: Сварочное производство | C5: 24 | D5: 0
A6: 38.02.06 | B6: Финансы | C6: 54 | D6: 5
A7: 25.02.08 | B7: Эксплуатация беспилотных авиационных систем | C7: 23 | D7: 0
A8: 35.02.16 | B8: Эксплуатация и ремонт сельскохозяйственной техники и оборудования | C8: 103 | D8: 8
A9: Всего | C9: 250 | D9: 13

Sheet СПО ВК
C1: Очная
C2: Всего | D2: Контракт
A3: 09.02.01 | B3: Компьютерные системы и комплексы | C3: 19 | D3: 0
A4: 19.02.12 | B4: Технология продуктов питания животного происхождения | C4: 31 | D4: 1
A5: 35.02.05 | B5: Агрономия | C5: 41 | D5: 5
A6: 36.02.01 | B6: Ветеринария | C6: 68 | D6: 30
A7: 38.02.01 | B7: Экономика и бухгалтерский учёт | C7: 41 | D7: 9
A8: 40.02.01 | B8: Право и организация социального обеспечения | C8: 20 | D8: 0
A9: 40.02.04 | B9: Юриспруденция | C9: 66 | D9: 66
A10: 44.02.01 | B10: Дошкольное образование | C10: 28 | D10: 4
A11: Всего | C11: 314 | D11: 115

Sheet СПО ЭФ
B1: Очная
B2: Всего | C2: Контракт
A3: 09.02.01 Компьютерные системы и комплексы | B3: 25 | C3: 6
A4: 44.02.02 Преподавание в начальных классах | B4: 73 | C4: 51
A5: 40.02.04 Юриспруденция | B5: 63 | C5: 63
A6: 39.02.01 Социальная работа | B6: 8 | C6: 8
A7: 40.02.02 Правоохранительная деятельность | B7: 53 | C7: 9
A8: 38.02.01 Экономика и бухгалтерский учёт (по отраслям) | B8: 17 | C8: 0
A9: 34.02.01 Сестринское дело | B9: 48 | C9: 48
A10: Всего | B10: =SUM(B3:B9) -> 287 | C10: =SUM(C3:C9) -> 185

Sheet ВО ЭФ 
B1: Очная | D1: Очно-заочная | F1: Заочная
B2: Всего | C2: Контракт | D2: Всего | E2: Контракт | F2: Всего | G2: Контракт
A3: 38.03.01 Экономика (Экономика предприятий и организаций) | B3: 17 | C3: 2 | D3: 26 | E3: 12 | F3: 0 | G3: 0
A4: 40.03.01 Юриспруденция (Государственно-правовой профиль) | B4: 40 | C4: 16 | D4: 0 | E4: 0 | F4: 0 | G4: 0
A5: 13.03.02 Электроэнергетика и электротехника (Электроэнергетика, электротехника и электромеханика) | B5: 0 | C5: 0 | D5: 0 | E5: 0 | F5: 78 | G5: 57
A6: Всего | B6: =SUM(B3:B5) -> 57 | C6: =SUM(C3:C5) -> 18 | D6: =SUM(D3:D5) -> 26 | E6: =SUM(E3:E5) -> 12 | F6: =SUM(F3:F5) -> 78 | G6: =SUM(G3:G5) -> 57

Sheet Бакалавриат
B1: Очная | D1: Очно-заочная | F1: Заочная
B2: Всего | C2: Контракт | D2: Всего | E2: Контракт | F2: Всего | G2: Контракт
A3: 01.00.00 Математика и механика | B3: 0 | C3: 0 | D3: 0 | E3: 0 | F3: 0 | G3: 0
A4: 02.00.00 Компьютерные и информационные науки | B4: 243 | C4: 31 | D4: 65 | E4: 2 | F4: 0 | G4: 0
A5: 04.00.00 Химия | B5: 48 | C5: 10 | D5: 0 | E5: 0 | F5: 0 | G5: 0
A6: 05.00.00 Науки о земле | B6: 72 | C6: 9 | D6: 0 | E6: 0 | F6: 63 | G6: 9
A7: 06.00.00 Биологические науки | B7: 102 | C7: 12 | D7: 91 | E7: 10 | F7: 0 | G7: 0
A8: 08.00.00 Техника и технологии строительства | B8: 20 | C8: 8 | D8: 0 | E8: 0 | F8: 0 | G8: 0
A9: 09.00.00 Информатика и вычислительная техника | B9: 0 | C9: 0 | D9: 0 | E9: 0 | F9: 0 | G9: 0
A10: 10.00.00 Информационная безопасность | B10: 33 | C10: 2 | D10: 0 | E10: 0 | F10: 0 | G10: 0
A11: 11.00.00 Электроника, радиотехника и системы связи | B11: 12 | C11: 1 | D11: 0 | E11: 0 | F11: 0 | G11: 0
A12: 13.00.00 Электро- и теплоэнергетика | B12: 192 | C12: 30 | D12: 75 | E12: 16 | F12: 531 | G12: 197
A13: 15.00.00 Машиностроение | B13: 244 | C13: 32 | D13: 0 | E13: 0 | F13: 189 | G13: 30
A14: 19.00.00 Промышленная экология и биотехнологии | B14: 161 | C14: 8 | D14: 0 | E14: 0 | F14: 212 | G14: 28
... A34: 56.00.00 Военное управление | B34: 0 | C34: 0 | D34: 0 | E34: 0 | F34: 0 | G34: 0
A35: Всего | B35: =SUM(B3:B34) -> 5057 | C35: =SUM(C3:C34) -> 793 | D35: =SUM(D3:D34) -> 2270 | E35: =SUM(E3:E34) -> 608 | F35: =SUM(F3:F34) -> 3833 | G35: =SUM(G3:G34) -> 798

Sheet Специалитет
B1: Очная | D1: Очно-заочная | F1: Заочная
B2: Всего | C2: Контракт | D2: Всего | E2: Контракт | F2: Всего | G2: Контракт
A3: 01.00.00 Математика и механика | B3: 0 | C3: 0 | D3: 0 | E3: 0 | F3: 0 | G3: 0
A4: 02.00.00 Компьютерные и информационные науки | B4: 0 | C4: 0 | D4: 0 | E4: 0 | F4: 0 | G4: 0
A5: 04.00.00 Химия | B5: 0 | C5: 0 | D5: 0 | E5: 0 | F5: 0 | G5: 0
A6: 05.00.00 Науки о земле | B6: 0 | C6: 0 | D6: 0 | E6: 0 | F6: 0 | G6: 0
A7: 06.00.00 Биологические науки | B7: 0 | C7: 0 | D7: 0 | E7: 0 | F7: 0 | G7: 0
A8: 08.00.00 Техника и технологии строительства | B8: 0 | C8: 0 | D8: 0 | E8: 0 | F8: 0 | G8: 0
A9: 09.00.00 Информатика и вычислительная техника | B9: 0 | C9: 0 | D9: 0 | E9: 0 | F9: 0 | G9: 0
A10: 10.00.00 Информационная безопасность | B10: 0 | C10: 0 | D10: 0 | E10: 0 | F10: 0 | G10: 0
A11: 11.00.00 Электроника, радиотехника и системы связи | B11: 0 | C11: 0 | D11: 0 | E11: 0 | F11: 0 | G11: 0
A12: 13.00.00 Электро- и теплоэнергетика | B12: 0 | C12: 0 | D12: 0 | E12: 0 | F12: 0 | G12: 0
A13: 15.00.00 Машиностроение | B13: 0 | C13: 0 | D13: 0 | E13: 0 | F13: 0 | G13: 0
A14: 19.00.00 Промышленная экология и биотехнологии | B14: 0 | C14: 0 | D14: 0 | E14: 0 | F14: 0 | G14: 0
... A34: 56.00.00 Военное управление | B34: 14 | C34: 3 | D34: 0 | E34: 0 | F34: 0 | G34: 0
A35: Всего | B35: =SUM(B3:B34) -> 351 | C35: =SUM(C3:C34) -> 144 | D35: =SUM(D3:D34) -> 0 | E35: =SUM(E3:E34) -> 0 | F35: =SUM(F3:F34) -> 237 | G35: =SUM(G3:G34) -> 36

Sheet Магистратура
B1: Очная | D1: Очно-заочная | F1: Заочная
B2: Всего | C2: Контракт | D2: Всего | E2: Контракт | F2: Всего | G2: Контракт
A3: 01.00.00 Математика и механика | B3: 0 | C3: 0 | D3: 0 | E3: 0 | F3: 0 | G3: 0
A4: 02.00.00 Компьютерные и информационные науки | B4: 37 | C4: 2 | D4: 11 | E4: 2 | F4: 0 | G4: 0
A5: 04.00.00 Химия | B5: 25 | C5: 1 | D5: 0 | E5: 0 | F5: 0 | G5: 0
A6: 05.00.00 Науки о земле | B6: 28 | C6: 0 | D6: 0 | E6: 0 | F6: 9 | G6: 0
A7: 06.00.00 Биологические науки | B7: 27 | C7: 6 | D7: 15 | E7: 15 | F7: 0 | G7: 0
A8: 08.00.00 Техника и технологии строительства | B8: 0 | C8: 0 | D8: 0 | E8: 0 | F8: 0 | G8: 0
A9: 09.00.00 Информатика и вычислительная техника | B9: 0 | C9: 0 | D9: 0 | E9: 0 | F9: 0 | G9: 0
A10: 10.00.00 Информационная безопасность | B10: 35 | C10: 5 | D10: 22 | E10: 4 | F10: 0 | G10: 0
A11: 11.00.00 Электроника, радиотехника и системы связи | B11: 0 | C11: 0 | D11: 0 | E11: 0 | F11: 0 | G11: 0
A12: 13.00.00 Электро- и теплоэнергетика | B12: 36 | C12: 0 | D12: 0 | E12: 0 | F12: 112 | G12: 73
A13: 15.00.00 Машиностроение | B13: 70 | C13: 1 | D13: 0 | E13: 0 | F13: 30 | G13: 1
A14: 19.00.00 Промышленная экология и биотехнологии | B14: 70 | C14: 1 | D14: 0 | E14: 0 | F14: 37 | G14: 3
... A34: 56.00.00 Военное управление | B34: 0 | C34: 0 | D34: 0 | E34: 0 | F34: 0 | G34: 0
A35: Всего | B35: =SUM(B3:B34) -> 1321 | C35: =SUM(C3:C34) -> 65 | D35: =SUM(D3:D34) -> 104 | E35: =SUM(E3:E34) -> 46 | F35: =SUM(F3:F34) -> 1489 | G35: =SUM(G3:G34) -> 534

Sheet УГСН Бакалавриат
A1: УГСН | B1: шифр | C1: направление/специальность | D1: профиль
A2: 01.00.00 Математика и механика | B2: 01.03.05 | C2: Статистика | D2: Статистика и анализ данных
A3: 02.00.00 Компьютерные и информационные науки | B3: 02.03.02 | C3: Фундаментальная информатика и информационные технологии | D3: Программирование и информационные технологии
A4: 04.00.00 Химия | B4: 04.03.01 | C4: Химия | D4: Органическая и биоорганическая химия
A5: 04.00.00 Химия | B5: 04.03.01 | D5: Химическая экспертиза и химический анализ в криминалистике
A6: 05.00.00 Науки о земле | B6: 05.03.02 | C6: География | D6: Физическая и общественная география
A7: 05.00.00 Науки о земле | B7: 05.03.06 | C7: Экология и природопользование | D7: Экология и природопользование
A8: 05.00.00 Науки о земле | B8: 05.03.06 | C8: Экология и природопользование | D8: Дистанционное зондирование и цифровые технологии в экологии
A9: 06.00.00 Биологические науки | B9: 06.03.01 | C9: Биология | D9: Биологические основы физической реабилитации
A10: 06.00.00 Биологические науки | B10: 06.03.02 | C10: Почвоведение | D10: Управление качеством почв и биотехнологий
A11: 06.00.00 Биологические науки | B11: 06.03.02 | C11: Почвоведение | D11: Управление земельными ресурсами
A12: 08.00.00 Техника и технологии строительства | B12: 08.03.01 | C12: Строительство | D12: Промышленное и гражданское строительство
A13: 08.00.00 Техника и технологии строительства | B13: 08.03.01 | D13: Строительство и эксплуатация автомобильных дорог
A14: 09.00.00 Информатика и вычислительная техника | B14: 09.03.01 | C14: Информатика и вычислительная техника | D14: (Информатика и вычеслительная техника)
A15: 10.00.00 Информационная безопасность | B15: 10.03.01 | C15: Информационная безопасность | D15: Безопасность компьютерных систем (по отрасли или в сфере профессиональной деятельности)
A16: 11.00.00 Электроника, радиотехника и системы связи | B16: 11.03.01 | C16: Радиотехника | D16: Цифровые системы локации, связи и навигации
A17: 13.00.00 Электро- и теплоэнергетика | B17: 13.03.02 | C17: Электроэнергетика и электротехника | D17: Электроэнергетика, электротехника и электромеханика
A18: 15.00.00 Машиностроение | B18: 15.03.02 | C18: Технологические машины и оборудование | D18: Компьютерный инжиниринг пищевых производств
A19: 15.00.00 Машиностроение | B19: 15.03.03 | C19: Прикладная механика | D19: Компьютерное проектирование и дизайн
A20: 15.00.00 Машиностроение | B20: 15.03.03 | C20: Прикладная механика | D20: Цифровые двойники изделий
A21: 15.00.00 Машиностроение | B21: 15.03.03 | C21: Прикладная механика | D21: Проектно-конструкторское обеспечение машиностроения
A22: 15.00.00 Машиностроение | B22: 15.03.05 | C22: Конструкторско-технологическое обеспечение машиностроительных производств | D22: Конструкторско-технологическое обеспечение машиностроительных производств
A23: 15.00.00 Машиностроение | B23: 15.03.06 | C23: Мехатроника и робототехника | D23: Промышленые роботы и роботизированные системы
A24: 15.00.00 Машиностроение | B24: 15.03.06 | C24: Мехатроника и робототехника | D24: Мехатронные и роботизированные технологические системы и комплексы
A25: 19.00.00 Промышленная экология и биотехнологии | B25: 19.03.01 | C25: Биотехнология | D25: Биохимия и биотехнология
... A67: 40.00.00 Юриспруденция | B67: 40.03.01 | C67: Юриспруденция | D67: Уголовно-правовый профиль
A68: 41.00.00 Политические науки и регионоведение | B68: 41.03.04 | C68: Политология
A69: 42.00.00 Средства массовой информации и информационно-библиотечное дело | B69: 42.03.01 | C69: Реклама и связи с общественностью | D69: Реклама связи с общественностью
A70: 42.00.00 Средства массовой информации и информационно-библиотечное дело | B70: 42.03.04 | C70: Телевидение
A71: 42.00.00 Средства массовой информации и информационно-библиотечное дело | B71: 42.03.05 | C71: Медиакоммуникации | D71: Медиакоммуникации в коммерческой и социальной сфере
A72: 43.00.00 Сервис и туризм | B72: 43.03.01 | C72: Сервис | D72: Сервис в индустрии моды и красоты
A73: 43.00.00 Сервис и туризм | B73: 43.03.02 | C73: Туризм | D73: Технология и организация услуг на предприятиях индустрии туризма
A74: 43.00.00 Сервис и туризм | B74: 43.03.03 | C74: Гостиничное дело | D74: Гостиничная деятельность
A75: 44.00.00 Образование и педагогические науки | B75: 44.03.01 | C75: Педагогическое образование | D75: Дошкольное образование
A76: 44.00.00 Образование и педагогические науки | B76: 44.03.01 | C76: Педагогическое образование | D76: Начальное образование
A77: 44.00.00 Образование и педагогические науки | B77: 44.03.01 | C77: Педагогическое образование | D77: Дополнительное образование в области хореографического искусства
A78: 44.00.00 Образование и педагогические науки | B78: 44.03.01 | C78: Педагогическое образование | D78: Музыка
A79: 44.00.00 Образование и педагогические науки | B79: 44.03.01 | C79: Педагогическое образование | D79: Физическая культура
A80: 44.00.00 Образование и педагогические науки | B80: 44.03.01 | C80: Педагогическое образование | D80: История
A81: 44.00.00 Образование и педагогические науки | B81: 44.03.02 | C81: Психолого-педагогическое образование | D81: Психология и социальная педагогика
...

Sheet УГСН Специалитет
A1: УГСН | B1: шифр | C1: направление/специальность | D1: профиль
A2: 10.00.00 Информационная безопасность | B2: 10.05.01 | C2: Компьютерная безопасность
A3: 38.00.00 Экономика и управление | B3: 38.05.01 | C3: Экономическая безопасность | D3: Экономико-правовое обеспечение экономической безопасности
A4: 40.00.00 Юриспруденция | B4: 40.05.01 | C4: Правовое обеспечение национальной безопасности | D4: Гражданско-правовая
A5: 40.00.00 Юриспруденция | B5: 40.05.02 | C5: Правоохранительная деятельность | D5: Административная деятельность полиции
A6: 40.00.00 Юриспруденция | B6: 40.05.04 | C6: Судебная и прокурорская деятельность | D6: Прокурорская деятельность
A7: 56.00.00 Военное управление | B7: 56.05.05 | C7: Военная журналистика | D7: Военная журналистика
A8: 56.00.00 Военное управление | B8: 56.05.08 | C8: Военно-политическая работа | D8: Военно-политическая работа в войсках (силах)

Sheet УГСН Магистратура
A1: УГСН | B1: шифр | C1: направление/специальность | D1: профиль
A2: 01.00.00 Математика и механика | B2: 01.04.05 | C2: Статистика | D2: Интеллектуальный анализ и управление данными
A3: 02.00.00 Компьютерные и информационные науки | B3: 02.04.02 | C3: Фундаментальная информатика и информационные технологии | D3: Программирование и информационные технологии
A4: 04.00.00 Химия | B4: 04.04.01 | C4: Химия | D4: Химическая экспертиза и химический анализ в криминалистике
A5: 05.00.00 Науки о земле | B5: 05.04.06 | C5: Экология и природопользование | D5: Устойчивое развитие и охрана природных объектов
A6: 05.00.00 Науки о земле | B6: 05.04.06 | C6: Экология и природопользование | D6: Экология и природопользование
A7: 06.00.00 Биологические науки | B7: 06.04.01 | C7: Биология | D7: Биомедицина с основами физической реабилитации
A8: 06.00.00 Биологические науки | B8: 06.04.01 | C8: Биология | D8: Организационно-управленческая деятельность в сфере здравоохранения
A9: 09.00.00 Информатика и вычислительная техника | B9: 09.04.01 | C9: Информатика и вычислительная техника
A10: 10.00.00 Информационная безопасность | B10: 10.04.01 | C10: Информационная безопасность | D10: Безопасность компьютерных систем
A11: 13.00.00 Электро- и теплоэнергетика | B11: 13.04.02 | C11: Электроэнергетика и электротехника | D11: Электроэнергетика, электротехника и электромеханика
A12: 15.00.00 Машиностроение | B12: 15.04.02 | C12: Технологические машины и оборудование | D12: Компьютерный инжиниринг пищевых производств
A13: 15.00.00 Машиностроение | B13: 15.04.03 | C13: Прикладная механика | D13: Компьютерный инжиниринг и вычислительная механика
A14: 15.00.00 Машиностроение | B14: 15.04.06 | C14: Мехатроника и робототехника | D14: Промышленные роботы и роботизированные системы
A15: 19.00.00 Промышленная экология и биотехнологии | B15: 19.04.01 | C15: Биотехнология | D15: Биохимия и биотехнология
A16: 19.00.00 Промышленная экология и биотехнологии | B16: 19.04.02 | C16: Продукты питания из растительного сырья | D16: Организация, ведение и проектирование технологий пищевых продуктов
A17: 19.00.00 Промышленная экология и биотехнологии | B17: 19.04.04 | C17: Технология продукции и организация общественного питания | D17: Стратегическое управление предприятиями сферы гостеприимства и общественного питания
A18: 19.00.00 Промышленная экология и биотехнологии | B18: 19.04.04 | C18: Технология продукции и организация общественного питания | D18: Технология и организация производства продуктов здорового питания
A19: 20.00.00 Техносферная безопасность и природообустройство | B19: 20.04.01 | C19: Техносферная безопасность | D19: Управление безопасностью труда
A20: 20.00.00 Техносферная безопасность и природообустройство | B20: 20.04.01 | C20: Техносферная безопасность | D20: Управление охраной труда
A21: 23.00.00 Техника и технологии наземного транспорта | B21: 23.04.02 | C21: Наземные транспортно-технологические комплексы
A22: 23.00.00 Техника и технологии наземного транспорта | B22: 23.04.03 | C22: Эксплуатация транспортно-технологических машин и комплексов
A23: 35.00.00 Сельское, лесное и рыбное хозяйство | B23: 35.04.01 | C23: Лесное дело | D23: Лесоустройство и управление лесными ресурсами
A24: 35.00.00 Сельское, лесное и рыбное хозяйство | B24: 35.04.04 | C24: Агрономия | D24: Агрономия
A25: 35.00.00 Сельское, лесное и рыбное хозяйство | B25: 35.04.05 | C25: Садоводство | D25: Плодоводство, овощеводство, виноградарство
A26: 35.00.00 Сельское, лесное и рыбное хозяйство | B26: 35.04.06 | C26: Агроинженерия | D26: Технические системы в агробизнесе
A27: 35.00.00 Сельское, лесное и рыбное хозяйство | B27: 35.04.09 | C27: Ландшафтная архитектура | D27: Садово-парковое и ландшафтное строительство
A28: 35.00.00 Сельское, лесное и рыбное хозяйство | B28: 35.04.10 | C28: Гидромелиорация | D28: Гидромелиорация
A29: 37.00.00 Психологические науки | B29: 37.04.01 | C29: Психология | D29: Практическая психология
A30: 38.00.00 Экономика и управление | B30: 38.04.01 | C30: Экономика | D30: Экономика предприятий
A31: 38.00.00 Экономика и управление | B31: 38.04.01 | C31: Экономика | D31: Экономика предприятий и организаций
A32: 38.00.00 Экономика и управление | B32: 38.04.01 | C32: Экономика | D32: Учет и аудит
A33: 38.00.00 Экономика и управление | B33: 38.04.01 | C33: Экономика | D33: Учет, анализ и аудит
A34: 38.00.00 Экономика и управление | B34: 38.04.02 | C34: Менеджмент | D34: Менеджмент
... A43: 40.00.00 Юриспруденция | B43: 40.04.01 | C43: Юриспруденция | D43: Юриспруденция
A44: 41.00.00 Политические науки и регионоведение | B44: 41.04.04 | C44: Политология
A45: 42.00.00 Средства массовой информации и информационно-библиотечное дело | B45: 42.04.02 | C45: Журналистика | D45: Журналистика
A46: 42.00.00 Средства массовой информации и информационно-библиотечное дело | B46: 42.04.05 | C46: Медиакоммуникации | D46: Медиакоммуникации в коммерческой и социальной сфере
A47: 43.00.00 Сервис и туризм | B47: 43.04.02 | C47: Туризм | D47: Организация стратегического управления предприятиями туристской сферы
A48: 43.00.00 Сервис и туризм | B48: 43.04.02 | C48: Туризм | D48: Организация стратегического управления предприятиями туристской сферы, туристическими продуктами и услугами
...
